Workbook

Sheet Tong_quan
A1: Bộ dữ liệu mẫu để sinh giọng nói trong xe cho huấn luyện ASR tiếng Việt – phiên bản 0.3
A2: 12/10/2026. Viết lại từ bản 0.2: tách case study theo mục đích dữ liệu và gắn mỗi yếu tố ảnh hưởng với bước xử lý đã trao đổi.
A4: TRẢ LỜI CÂU HỎI: BỘ MẪU CÂU CÓ PHẢI ĐÁP ỨNG CÁC YẾU TỐ ẢNH HƯỞNG KHÔNG?
A5: Có, nhưng chỉ một phần | B5: Bộ mẫu câu phải đáp ứng các yếu tố mà chính câu quyết định (số, địa chỉ, tên riêng, từ vùng, câu cụt, độ dài...). Các yếu tố còn lại do bước khác xử lý: chọn giọng, điều khiển TTS, trộn nhiễu sau TTS, hoặc chỉ đo ở bộ đánh giá. Sheet Buoc_xu_ly và Yeu_to cho biết yếu tố nào ở bước nào.
A6: Số yếu tố do câu quyết định (bước 1) | B6: =COUNTIF(Yeu_to!$G$4:$G$74,"1.*") -> 15
A7: Số yếu tố do bước khác quyết định | B7: =COUNTA(Yeu_to!$C$4:$C$74)-B6 -> 56
A8: Tổng số yếu tố | B8: =COUNTA(Yeu_to!$C$4:$C$74) -> 71
A10: QUY TRÌNH TỔNG QUÁT
A11: Bước 1 | B11: Chọn giọng thật sạch từ bộ dữ liệu có nhãn vùng (Bắc, Trung, Nam) và chọn đoạn tham chiếu.
A12: Bước 2 | B12: Clone hoặc tinh chỉnh TTS (zero-shot trước; tinh chỉnh theo vùng nếu giọng vùng bị kéo về giọng chuẩn). Mục tiêu của TTS là sinh dữ liệu, không phải huấn luyện ASR.
A13: Bước 3 | B13: Sinh câu của người dùng trong xe (M1, M2) và tập đối chiếu ngoài miền xe (M3) bằng cùng giọng, dạng âm thanh sạch.
A14: Bước 4 | B14: Trộn nhiễu xe thật, đáp ứng xung khoang xe, giọng người khác, nhạc; đặt SNR; ghi lại nguồn ồn.
A15: Bước 5 | B15: Huấn luyện ASR bằng dữ liệu thật ngoài miền xe cộng dữ liệu sinh đã trộn nhiễu.
A16: Bước 6 | B16: Đánh giá trên bộ thật giữ riêng; bộ M4 dùng để chọn mô hình TTS trước khi sinh hàng loạt.
A18: CÁC SHEET
A19: Muc_dich | B19: 5 mục đích dữ liệu M1–M5: ai nói, dùng vào đâu, có vào huấn luyện ASR không.
A20: Case_study | B20: 12 case study, mỗi case gắn mục đích chính, phần người dùng và phần trợ lý, yếu tố trọng yếu, preset môi trường.
A21: Yeu_to | B21: 71 yếu tố đã trao đổi, mỗi yếu tố gắn bước xử lý chính, cách xử lý, bằng chứng, số câu mẫu phủ.
A22: Buoc_xu_ly | B22: Số yếu tố theo từng bước xử lý.
A23: Ma_tran | B23: Case × yếu tố do câu quyết định, kèm số câu mẫu phủ từng yếu tố.
A24: Mau_khung | B24: Mẫu câu × khe thông tin; sức chứa tổ hợp để phủ số câu cần.
A25: Mau_cau | B25: Câu mẫu của người dùng (M1, M2) và câu chẩn đoán (M4), có nhãn yếu tố.
A26: Chi_tieu | B26: Số người nói, số câu, giờ âm thanh, tỷ lệ sinh/thật; ô vàng sửa được.
A27: Preset_moi_truong | B27: 17 preset môi trường kèm nguồn ồn thật có thể dùng.
A28: Danh_gia | B28: Điểm giải pháp và điểm giữ giọng vùng (nhận định của mình, không phải số đo).
A29: Ho_so_nguoi_noi | B29: Mẫu hồ sơ giọng thật sẽ clone.
A30: Nguon_giay_phep | B30: Nguồn dữ liệu và tình trạng giấy phép.
... A32: Tu_dia_phuong, Tu_vung | B32: Từ vựng vùng miền và danh sách giá trị cho ô chọn.
A34: LƯU Ý
A35: Số liệu | B35: Các hạn ngạch (số người nói, số câu, tỷ lệ) lấy từ các bài báo tiếng Anh, Hàn, Mân Nam; chưa ai kiểm cho tiếng Việt. Xem Danh_gia và Tai_lieu.
A36: Câu mẫu | B36: Câu mẫu chỉ để minh họa cấu trúc và nhãn. Từ vựng và cách đọc từng vùng cần người bản ngữ duyệt trước khi dùng.
A37: M3 | B37: Tập đối chiếu ngoài miền xe chưa có transcript vì chưa chọn bộ thật; chỉ cần lấy từ bộ thật đã chọn, không dùng câu của tập kiểm thử.
A39: THAM SỐ ƯỚC LƯỢNG THỜI LƯỢNG (sửa được)
A40: Tốc độ nói để ước thời lượng | B40: 4.5 | C40: âm tiết/giây | D40: Giá trị vừa của bản 0.2 (chọn tạm, chưa đo).

Sheet Muc_dich
A1: Mục đích dữ liệu M1–M5
A2: Mỗi dòng của Mau_cau thuộc đúng một mục đích. Cột xanh lá tự tính.
A3: Mã | B3: Tên | C3: Ai nói | D3: Dùng để làm gì | E3: Vào huấn luyện ASR | F3: Vào kiểm thử | G3: Nguồn văn bản | H3: Nguồn giọng | I3: Bước áp dụng | J3: Ghi chú | K3: Số câu mẫu trong Mau_cau
A4: M1 | B4: Lệnh và câu hỏi của người dùng trong xe (sinh) | C4: Người dùng | D4: Dữ liệu chính cần sinh: những gì người lái hoặc hành khách nói với trợ lý. Đây là thứ ASR phải nhận ra. | E4: Có | F4: Một phần giữ lại, chia theo người nói và mẫu câu | G4: Mẫu câu × khe + diễn đạt lại bằng LLM, người bản ngữ duyệt (xem Mau_khung) | H4: Clone từ giọng thật có nhãn vùng; đoạn tham chiếu cùng vùng với từ vựng của câu | I4: Bước 1 đến 5 (mọi yếu tố phía người nói và nhiễu) | J4: Phần lớn số câu nằm ở đây. Chưa có paper đo trên tiếng Việt. | K4: =COUNTIF(Mau_cau!$B$4:$B$300,A4) -> 53
A5: M2 | B5: Câu trả lời ngắn cho trợ lý (sinh) | C5: Người dùng | D5: Câu 1 đến 3 âm tiết đáp lại câu hỏi của hệ thống: có, không, cái thứ hai, hủy, một con số. | E5: Có | F5: Một phần giữ lại | G5: Danh sách câu trả lời theo từng loại câu hỏi của hệ thống | H5: Như M1 | I5: Bước 1 đến 5 | J5: Câu rất ngắn là điểm TTS dễ lỗi (PhoAudiobook: XTTS-v2 WER 37,81% trên VIVOS); cần theo dõi riêng. | K5: =COUNTIF(Mau_cau!$B$4:$B$300,A5) -> 12
A6: M3 | B6: Tập đối chiếu ngoài miền xe (sinh) | C6: Người đọc | D6: Cùng giọng, cùng quy trình sinh và trộn nhiễu như M1 nhưng câu lấy từ tập thật ngoài miền xe. Dùng để tách ảnh hưởng của 'giọng sinh' khỏi ảnh hưởng của 'miền xe', và tránh việc ASR học 'âm thanh kiểu TTS là lệnh xe'. | E6: Có | F6: Không | G6: Transcript của bộ thật ngoài miền xe (chưa chọn; kiểm giấy phép từng bộ) | H6: Clone từ cùng kho giọng như M1 | I6: Bước 2 đến 5 | J6: Đề xuất của mình, chưa paper nào kiểm riêng thiết kế này. Không dùng câu của tập kiểm thử. | K6: =COUNTIF(Mau_cau!$B$4:$B$300,A6) -> 0
A7: M4 | B7: Câu chẩn đoán để chọn mô hình TTS | C7: Người đọc | D7: Bộ nhỏ chạy trên các mô hình TTS chưa tinh chỉnh để so sánh: câu rất ngắn, số, tên riêng, cặp thanh điệu, từ vùng, chuyển mã. | E7: Không | F7: Có (đánh giá TTS) | G7: Viết tay, cố định | H7: Một vài giọng mỗi vùng | I7: Chỉ dùng ở bước chọn mô hình | J7: Đo WER hai ASR, độ giống người nói, độ giống giọng vùng, nghe bản ngữ. | K7: =COUNTIF(Mau_cau!$B$4:$B$300,A7) -> 14
A8: M5 | B8: Lời trợ lý phát ra loa trong xe | C8: Trợ lý | D8: Câu dẫn đường, cảnh báo, xác nhận mà trợ lý nói (47 câu mẫu của bảng v0.2 thuộc loại này). | E8: Không | F8: Không (ngoài phạm vi ASR) | G8: Bảng v0.2 (Mau_du_lieu cũ) | H8: Giọng trợ lý | I8: Ngoài phạm vi ASR; thuộc đánh giá TTS sản phẩm | J8: Giữ cho giai đoạn sau. Không đưa vào dữ liệu huấn luyện ASR. | K8: =COUNTIF(Mau_cau!$B$4:$B$300,A8) -> 0

Sheet Case_study
A1: 12 case study theo mục đích
A2: Mục đích chính: M1 người dùng nói lệnh, M2 câu trả lời ngắn, M5 trợ lý nói. Liên quan ASR là nhận định của mình dựa trên việc ai nói chủ yếu.
A3: Mã | B3: Tên case | C3: Mô tả | D3: Mục đích chính | E3: Liên quan ASR | F3: Phần người dùng nói (M1, M2) | G3: Phần trợ lý nói (M5, ngoài ASR) | H3: Lý do và điểm khó | I3: Yếu tố trọng yếu (mã) | J3: Preset môi trường | K3: Ghi chú | L3: Câu mẫu M1 | M3: Câu mẫu M2 | N3: Trọng số (Chi_tieu) | O3: Số câu mục tiêu (Chi_tieu)
A4: CS01 | B4: Dẫn đường | C4: Chỉ đường từng chặng: rẽ, khoảng cách, tên đường, đích đến. | D4: M1 | E4: Có | F4: dẫn đường đến địa chỉ; hỏi còn bao xa; tìm đường tránh tắc; hỏi giờ đến; hủy dẫn đường | G4: báo rẽ, báo khoảng cách, báo đã đến, đổi lộ trình | H4: Người dùng nói địa chỉ, số nhà, tên đường nhiều nhất; tên riêng và từ địa phương (hẻm/ngõ, quẹo/rẽ) là lỗi hay gặp. | I4: E03; E04; S51; S53; S54; D01 | J4: E02; E03; E12; E10; E13 | L4: =COUNTIFS(Mau_cau!$C$4:$C$300,A4,Mau_cau!$B$4:$B$300,"M1") -> 8 | M4: =COUNTIFS(Mau_cau!$C$4:$C$300,A4,Mau_cau!$B$4:$B$300,"M2") -> 0 | N4: =INDEX(Chi_tieu!$C$27:$C$38,MATCH(A4,Chi_tieu!$A$27:$A$38,0)) -> 0.15 | O4: =INDEX(Chi_tieu!$D$27:$D$38,MATCH(A4,Chi_tieu!$A$27:$A$38,0)) -> 1500
A5: CS02 | B5: Cảnh báo an toàn (ADAS) | C5: Cảnh báo va chạm, lệch làn, mệt mỏi, điểm mù, quá tốc độ. | D5: M5 | E5: Hầu như không | F5: tắt hoặc bật cảnh báo; nói 'tôi ổn' khi bị nhắc mệt | G5: va chạm phía trước, lệch làn, người lái mệt, điểm mù, vượt tốc độ | H5: Gần như toàn bộ do hệ thống tự phát. Phần người dùng rất nhỏ nên chỉ lấy một lát để thử giọng mệt mỏi. | I5: D03; S21; S22; S23 | J5: E03; E05; E07; E04; E14 | K5: Trọng số sinh thấp. | L5: =COUNTIFS(Mau_cau!$C$4:$C$300,A5,Mau_cau!$B$4:$B$300,"M1") -> 2 | M5: =COUNTIFS(Mau_cau!$C$4:$C$300,A5,Mau_cau!$B$4:$B$300,"M2") -> 0 | N5: =INDEX(Chi_tieu!$C$27:$C$38,MATCH(A5,Chi_tieu!$A$27:$A$38,0)) -> 0.03 | O5: =INDEX(Chi_tieu!$D$27:$D$38,MATCH(A5,Chi_tieu!$A$27:$A$38,0)) -> 300
A6: CS03 | B6: Điều khiển xe | C6: Điều chỉnh điều hòa, ghế, cửa kính, cửa sổ trời, đèn trong xe bằng giọng nói. | D6: M1 | E6: Có | F6: đặt nhiệt độ; sưởi ghế; hạ kính; chỉnh quạt; bật sấy kính | G6: xác nhận thông số | H6: Lệnh ngắn, nhiều thông số; có từ vùng (kính/kiếng, điều hòa/máy lạnh) và chuyển mã (air-con). | I6: E02; E03; S51; S52; S55; A04 | J6: E01; E02; E06; E05 | K6: Lõi của bộ M1. | L6: =COUNTIFS(Mau_cau!$C$4:$C$300,A6,Mau_cau!$B$4:$B$300,"M1") -> 9 | M6: =COUNTIFS(Mau_cau!$C$4:$C$300,A6,Mau_cau!$B$4:$B$300,"M2") -> 0 | N6: =INDEX(Chi_tieu!$C$27:$C$38,MATCH(A6,Chi_tieu!$A$27:$A$38,0)) -> 0.14 | O6: =INDEX(Chi_tieu!$D$27:$D$38,MATCH(A6,Chi_tieu!$A$27:$A$38,0)) -> 1400
A7: CS04 | B7: Giải trí (nhạc, radio) | C7: Phát nhạc, chuyển kênh radio, chỉnh âm lượng. | D7: M1 | E7: Có | F7: mở bài hoặc danh sách nhạc; chuyển kênh; chỉnh âm lượng; hỏi đang phát gì | G7: xác nhận bài, kênh | H7: Tên bài, tên kênh, từ mượn tiếng Anh; nhạc đang phát là nguồn ồn chính. | I7: E05; E07; S55; A07; A14 | J7: E07; E02; E08; E17 | L7: =COUNTIFS(Mau_cau!$C$4:$C$300,A7,Mau_cau!$B$4:$B$300,"M1") -> 5 | M7: =COUNTIFS(Mau_cau!$C$4:$C$300,A7,Mau_cau!$B$4:$B$300,"M2") -> 0 | N7: =INDEX(Chi_tieu!$C$27:$C$38,MATCH(A7,Chi_tieu!$A$27:$A$38,0)) -> 0.12 | O7: =INDEX(Chi_tieu!$D$27:$D$38,MATCH(A7,Chi_tieu!$A$27:$A$38,0)) -> 1200
A8: CS05 | B8: Điện thoại và tin nhắn | C8: Báo cuộc gọi, đọc tin nhắn, gọi theo số hoặc tên. | D8: M1 | E8: Có | F8: gọi tên; gọi số; đọc tin nhắn; trả lời tin nhắn | G8: báo cuộc gọi đến, đọc tin nhắn | H8: Số điện thoại, tên người, xưng hô theo vùng (mạ/má/mẹ); hành khách nói chen. | I8: E03; E06; S52; S53; A14 | J8: E11; E02; E07; E15 | L8: =COUNTIFS(Mau_cau!$C$4:$C$300,A8,Mau_cau!$B$4:$B$300,"M1") -> 6 | M8: =COUNTIFS(Mau_cau!$C$4:$C$300,A8,Mau_cau!$B$4:$B$300,"M2") -> 0 | N8: =INDEX(Chi_tieu!$C$27:$C$38,MATCH(A8,Chi_tieu!$A$27:$A$38,0)) -> 0.12 | O8: =INDEX(Chi_tieu!$D$27:$D$38,MATCH(A8,Chi_tieu!$A$27:$A$38,0)) -> 1200
A9: CS06 | B9: Trạng thái xe và bảo dưỡng | C9: Báo áp suất lốp, nhiên liệu, bảo dưỡng định kỳ, đèn báo. | D9: M1 | E9: Một phần | F9: hỏi áp suất lốp; hỏi nhiên liệu còn lại; hỏi lịch bảo dưỡng | G9: cảnh báo áp suất, nhiên liệu, đèn báo | H9: Phần lớn là hệ thống báo; người dùng chỉ hỏi lại, câu hỏi ngắn. | I9: E03; E07; D01 | J9: E01; E02; E03 | L9: =COUNTIFS(Mau_cau!$C$4:$C$300,A9,Mau_cau!$B$4:$B$300,"M1") -> 3 | M9: =COUNTIFS(Mau_cau!$C$4:$C$300,A9,Mau_cau!$B$4:$B$300,"M2") -> 0 | N9: =INDEX(Chi_tieu!$C$27:$C$38,MATCH(A9,Chi_tieu!$A$27:$A$38,0)) -> 0.05 | O9: =INDEX(Chi_tieu!$D$27:$D$38,MATCH(A9,Chi_tieu!$A$27:$A$38,0)) -> 500
A10: CS07 | B10: Sạc xe điện và trạm nhiên liệu | C10: Hỏi tình trạng pin, tìm trạm sạc, ước tính thời gian và chi phí sạc. | D10: M1 | E10: Có | F10: hỏi pin còn lại; tìm trạm sạc; hỏi thời gian và chi phí sạc | G10: báo pin, trạm gần nhất, chi phí | H10: Số thập phân, phần trăm, tiền VND; cách đọc nghìn/ngàn theo vùng. | I10: E03; E07; S53 | J10: E01; E08; E02 | L10: =COUNTIFS(Mau_cau!$C$4:$C$300,A10,Mau_cau!$B$4:$B$300,"M1") -> 4 | M10: =COUNTIFS(Mau_cau!$C$4:$C$300,A10,Mau_cau!$B$4:$B$300,"M2") -> 0 | N10: =INDEX(Chi_tieu!$C$27:$C$38,MATCH(A10,Chi_tieu!$A$27:$A$38,0)) -> 0.06 | O10: =INDEX(Chi_tieu!$D$27:$D$38,MATCH(A10,Chi_tieu!$A$27:$A$38,0)) -> 600
A11: CS08 | B11: Giao thông và thời tiết | C11: Báo tắc đường, tai nạn, giờ đến dự kiến, dự báo thời tiết. | D11: M1 | E11: Có | F11: hỏi tắc đường phía trước; hỏi thời tiết; hỏi giờ đến | G11: bản tin giao thông, thời tiết | H11: Tên địa danh, giờ, khoảng giá trị; từ vùng (kẹt xe/tắc đường). | I11: E03; E04; S51; D01 | J11: E12; E04; E02 | L11: =COUNTIFS(Mau_cau!$C$4:$C$300,A11,Mau_cau!$B$4:$B$300,"M1") -> 4 | M11: =COUNTIFS(Mau_cau!$C$4:$C$300,A11,Mau_cau!$B$4:$B$300,"M2") -> 0 | N11: =INDEX(Chi_tieu!$C$27:$C$38,MATCH(A11,Chi_tieu!$A$27:$A$38,0)) -> 0.07 | O11: =INDEX(Chi_tieu!$D$27:$D$38,MATCH(A11,Chi_tieu!$A$27:$A$38,0)) -> 700
A12: CS09 | B12: Khẩn cấp và cứu hộ | C12: Phát hiện va chạm nghiêm trọng, sự cố pin, gọi cấp cứu và cứu hộ. | D12: M1 | E12: Một phần | F12: gọi cấp cứu; nói 'tôi ổn'; kêu cứu; gọi cứu hộ | G12: hỏi thăm, gửi vị trí, hướng dẫn rời xe | H12: Người dùng nói trong căng thẳng, to, nhanh, cao giọng (Lombard, cảm xúc). Khó sinh và chưa có bằng chứng; số mẫu ít. | I12: D03; S21; S22; S23; S24; E08 | J12: E03; E01; E04; E17 | K12: Khó nhất về mặt giọng. | L12: =COUNTIFS(Mau_cau!$C$4:$C$300,A12,Mau_cau!$B$4:$B$300,"M1") -> 4 | M12: =COUNTIFS(Mau_cau!$C$4:$C$300,A12,Mau_cau!$B$4:$B$300,"M2") -> 0 | N12: =INDEX(Chi_tieu!$C$27:$C$38,MATCH(A12,Chi_tieu!$A$27:$A$38,0)) -> 0.03 | O12: =INDEX(Chi_tieu!$D$27:$D$38,MATCH(A12,Chi_tieu!$A$27:$A$38,0)) -> 300
A13: CS10 | B13: Hội thoại và gợi ý chủ động | C13: Gợi ý lịch trình, quán gần đây, nhắc việc, hỏi đáp tự nhiên. | D13: M1 | E13: Có | F13: nhắc việc; hỏi quán gần đây; cảm ơn; hỏi đáp chung | G13: gợi ý, nhắc lịch | H13: Câu dài hơn, câu cụt, chuyển mã Anh–Việt; đa dạng diễn đạt lớn nhất. | I13: E05; E06; E08; S23; S33; S55 | J13: E01; E02; E08 | L13: =COUNTIFS(Mau_cau!$C$4:$C$300,A13,Mau_cau!$B$4:$B$300,"M1") -> 5 | M13: =COUNTIFS(Mau_cau!$C$4:$C$300,A13,Mau_cau!$B$4:$B$300,"M2") -> 0 | N13: =INDEX(Chi_tieu!$C$27:$C$38,MATCH(A13,Chi_tieu!$A$27:$A$38,0)) -> 0.11 | O13: =INDEX(Chi_tieu!$D$27:$D$38,MATCH(A13,Chi_tieu!$A$27:$A$38,0)) -> 1100
A14: CS11 | B14: Hành khách và trẻ em | C14: Thông báo cho khoang sau, nhắc dây an toàn ghế sau, nói chuyện với trẻ. | D14: M1 | E14: Một phần | F14: trẻ nhờ mở nhạc; người lớn ra lệnh cho khoang sau; tắt loa sau | G14: nhắc dây an toàn, chế độ yên tĩnh khoang sau | H14: Cần giọng trẻ em, vốn không tạo được từ giọng người lớn một cách đáng tin; cần nguồn giọng trẻ thật có đồng ý. | I14: S12; A14; E06; S21 | J14: E02; E07; E08 | K14: Chỉ làm khi có nguồn giọng trẻ em. | L14: =COUNTIFS(Mau_cau!$C$4:$C$300,A14,Mau_cau!$B$4:$B$300,"M1") -> 3 | M14: =COUNTIFS(Mau_cau!$C$4:$C$300,A14,Mau_cau!$B$4:$B$300,"M2") -> 0 | N14: =INDEX(Chi_tieu!$C$27:$C$38,MATCH(A14,Chi_tieu!$A$27:$A$38,0)) -> 0.03 | O14: =INDEX(Chi_tieu!$D$27:$D$38,MATCH(A14,Chi_tieu!$A$27:$A$38,0)) -> 300
A15: CS12 | B15: Lỗi, làm rõ và ngoại tuyến | C15: Xử lý khi không nghe rõ, trùng tên, mất mạng, tính năng chưa hỗ trợ. | D15: M2 | E15: Có | F15: nói lại; sửa 'không phải, ý tôi là…'; chọn cái thứ hai; hủy | G15: xin lỗi, hỏi lại, báo mất mạng | H15: Phần lớn là câu trả lời rất ngắn, đúng chỗ TTS dễ lỗi và ASR dễ nhầm. | I15: E08; S23; S33; E06 | J15: E02; E03; E07; E10; E16 | K15: Gần hết là M2. | L15: =COUNTIFS(Mau_cau!$C$4:$C$300,A15,Mau_cau!$B$4:$B$300,"M1") -> 0 | M15: =COUNTIFS(Mau_cau!$C$4:$C$300,A15,Mau_cau!$B$4:$B$300,"M2") -> 12 | N15: =INDEX(Chi_tieu!$C$27:$C$38,MATCH(A15,Chi_tieu!$A$27:$A$38,0)) -> 0.09 | O15: =INDEX(Chi_tieu!$D$27:$D$38,MATCH(A15,Chi_tieu!$A$27:$A$38,0)) -> 900
A17: Mã yếu tố dùng ở cột I xem sheet Yeu_to. Số câu mục tiêu và trọng số lấy từ sheet Chi_tieu (sửa ở đó).

Sheet Yeu_to
A1: 71 yếu tố ảnh hưởng: bước xử lý chính và cách xử lý
A2: Bước xử lý chính là nơi yếu tố được giải quyết; bước phụ là nơi cần kiểm hoặc hỗ trợ. Bằng chứng ghi nguồn và giới hạn; 'Chưa có bằng chứng đã đọc' nghĩa là mình chưa có bài báo nào cho điểm này.
A3: Nhóm | B3: Nhóm con | C3: Mã | D3: Yếu tố | E3: Mức | F3: Phía | G3: Bước xử lý chính | H3: Bước phụ | I3: Cách xử lý | J3: Bằng chứng | K3: Tác động | L3: Chỉ số đo | M3: Ưu tiên | N3: Dữ liệu thật | O3: Số câu mẫu phủ
A4: 1. Nhiễu và âm thanh nền | B4: 1.1 Nguồn ồn từ chính chiếc xe | C4: A01 | D4: Tiếng lốp và mặt đường | E4: Loại mặt đường (nhựa mịn, bê tông, sỏi); tốc độ. Chỉ dẫn: Tăng theo tốc độ, năng lượng ở dải thấp đến trung | F4: Cả hai | G4: 4. Trộn nhiễu và mô phỏng khoang xe (sau TTS) | I4: Trộn sau khi có âm thanh sạch; ghi nguồn ồn và snr_actual_dB; dùng nhiều nguồn ồn và ồn đổi giữa câu. | J4: Trộn nhiễu giảm WER khoảng 5,1%, nhiễu cộng vang khoảng 6,6% (Ogun et al. 2025; Common Voice tiếng Anh, 50 giờ thật; cần kiểm chứng cho tiếng Việt). | K4: Che nguyên âm và thanh điệu | L4: WER/CER theo SNR; nghe kiểm thanh điệu | M4: Cao | N4: Thu mẫu nhỏ làm mốc | O4: Không do câu quyết định
A5: 1. Nhiễu và âm thanh nền | B5: 1.1 Nguồn ồn từ chính chiếc xe | C5: A02 | D5: Tiếng gió | E5: Tốc độ; cửa kính; cửa sổ trời. Chỉ dẫn: Tăng mạnh khi mở cửa kính | F5: Cả hai | G5: 4. Trộn nhiễu và mô phỏng khoang xe (sau TTS) | I5: Trộn sau khi có âm thanh sạch; ghi nguồn ồn và snr_actual_dB; dùng nhiều nguồn ồn và ồn đổi giữa câu. | J5: Trộn nhiễu giảm WER khoảng 5,1%, nhiễu cộng vang khoảng 6,6% (Ogun et al. 2025; Common Voice tiếng Anh, 50 giờ thật; cần kiểm chứng cho tiếng Việt). | K5: Nhiễu băng rộng, che phụ âm xát | L5: WER; độ rõ phụ âm | M5: Cao | N5: Thu mẫu nhỏ làm mốc | O5: Không do câu quyết định
A6: 1. Nhiễu và âm thanh nền | B6: 1.1 Nguồn ồn từ chính chiếc xe | C6: A03 | D6: Động cơ hoặc mô-tơ điện | E6: Xăng/dầu/hybrid/điện; vòng tua. Chỉ dẫn: Xe điện nền thấp nhưng có tiếng rít điện | F6: Cả hai | G6: 4. Trộn nhiễu và mô phỏng khoang xe (sau TTS) | I6: Trộn sau khi có âm thanh sạch; ghi nguồn ồn và snr_actual_dB; dùng nhiều nguồn ồn và ồn đổi giữa câu. | J6: Trộn nhiễu giảm WER khoảng 5,1%, nhiễu cộng vang khoảng 6,6% (Ogun et al. 2025; Common Voice tiếng Anh, 50 giờ thật; cần kiểm chứng cho tiếng Việt). | K6: Xe điện làm lỗi nhỏ của TTS lộ rõ hơn | L6: MOS; WER | M6: Trung bình | N6: Thu mẫu nhỏ làm mốc | O6: Không do câu quyết định
A7: 1. Nhiễu và âm thanh nền | B7: 1.1 Nguồn ồn từ chính chiếc xe | C7: A04 | D7: Quạt điều hòa | E7: Mức 0–5; hướng gió. Chỉ dẫn: Mức cao tạo nhiễu băng rộng ở trung–cao | F7: Cả hai | G7: 4. Trộn nhiễu và mô phỏng khoang xe (sau TTS) | I7: Trộn sau khi có âm thanh sạch; ghi nguồn ồn và snr_actual_dB; dùng nhiều nguồn ồn và ồn đổi giữa câu. | J7: Trộn nhiễu giảm WER khoảng 5,1%, nhiễu cộng vang khoảng 6,6% (Ogun et al. 2025; Common Voice tiếng Anh, 50 giờ thật; cần kiểm chứng cho tiếng Việt). | K7: Che phụ âm, giảm độ rõ | L7: WER theo mức quạt | M7: Trung bình | N7: Thu mẫu nhỏ làm mốc | O7: Không do câu quyết định
A8: 1. Nhiễu và âm thanh nền | B8: 1.1 Nguồn ồn từ chính chiếc xe | C8: A09 | D8: Rung và tiếng cấu trúc | E8: Đường xấu, gờ giảm tốc, mặt cầu. Chỉ dẫn: Xung va chạm ngắt quãng | F8: Cả hai | G8: 4. Trộn nhiễu và mô phỏng khoang xe (sau TTS) | I8: Trộn sau khi có âm thanh sạch; ghi nguồn ồn và snr_actual_dB; dùng nhiều nguồn ồn và ồn đổi giữa câu. | J8: Trộn nhiễu giảm WER khoảng 5,1%, nhiễu cộng vang khoảng 6,6% (Ogun et al. 2025; Common Voice tiếng Anh, 50 giờ thật; cần kiểm chứng cho tiếng Việt). | K8: Ngắt âm tiết ngắn | L8: WER | M8: Thấp | N8: Thu mẫu nhỏ làm mốc | O8: Không do câu quyết định
A9: 1. Nhiễu và âm thanh nền | B9: 1.2 Nguồn ồn từ bên ngoài xe | C9: A05 | D9: Mưa và gạt nước | E9: Mưa nhỏ/to; tốc độ gạt. Chỉ dẫn: Mưa to là một trong các nền ồn cao | F9: Cả hai | G9: 4. Trộn nhiễu và mô phỏng khoang xe (sau TTS) | I9: Trộn sau khi có âm thanh sạch; ghi nguồn ồn và snr_actual_dB; dùng nhiều nguồn ồn và ồn đổi giữa câu. | J9: Trộn nhiễu giảm WER khoảng 5,1%, nhiễu cộng vang khoảng 6,6% (Ogun et al. 2025; Common Voice tiếng Anh, 50 giờ thật; cần kiểm chứng cho tiếng Việt). | K9: Nhiễu xung lặp theo nhịp gạt | L9: WER; ổn định giọng | M9: Trung bình | N9: Thu mẫu nhỏ làm mốc | O9: Không do câu quyết định
A10: 1. Nhiễu và âm thanh nền | B10: 1.2 Nguồn ồn từ bên ngoài xe | C10: A06 | D10: Giao thông bên ngoài (còi, xe máy) | E10: Mật độ xe máy; còi liên tục. Chỉ dẫn: Xung ngắn, cường độ cao | F10: Cả hai | G10: 4. Trộn nhiễu và mô phỏng khoang xe (sau TTS) | I10: Trộn sau khi có âm thanh sạch; ghi nguồn ồn và snr_actual_dB; dùng nhiều nguồn ồn và ồn đổi giữa câu. | J10: Trộn nhiễu giảm WER khoảng 5,1%, nhiễu cộng vang khoảng 6,6% (Ogun et al. 2025; Common Voice tiếng Anh, 50 giờ thật; cần kiểm chứng cho tiếng Việt). | K10: Che mất âm tiết ngắn; cảnh báo ngắn dễ bị nuốt | L10: WER; tỷ lệ âm tiết bị mất | M10: Cao | N10: Thu mẫu nhỏ làm mốc | O10: Không do câu quyết định
A11: 1. Nhiễu và âm thanh nền | B11: 1.2 Nguồn ồn từ bên ngoài xe | C11: A10 | D11: Hầm, cầu, gầm cầu | E11: Phản xạ lớn, nền ồn tăng, có thể mất mạng. Chỉ dẫn: Vang dài | F11: Cả hai | G11: 4. Trộn nhiễu và mô phỏng khoang xe (sau TTS) | I11: Trộn sau khi có âm thanh sạch; ghi nguồn ồn và snr_actual_dB; dùng nhiều nguồn ồn và ồn đổi giữa câu. | J11: Trộn nhiễu giảm WER khoảng 5,1%, nhiễu cộng vang khoảng 6,6% (Ogun et al. 2025; Common Voice tiếng Anh, 50 giờ thật; cần kiểm chứng cho tiếng Việt). | K11: Vang làm nhòe âm tiết; mất mạng ảnh hưởng TTS đám mây | L11: WER; hoạt động ngoại tuyến | M11: Trung bình | N11: Thu mẫu nhỏ làm mốc | O11: Không do câu quyết định
A12: 1. Nhiễu và âm thanh nền | B12: 1.3 Nguồn ồn từ bên trong khoang | C12: A07 | D12: Nhạc hoặc radio đang phát | E12: Nhỏ/lớn; có lời hay không lời; bật/tắt ducking. Chỉ dẫn: Cạnh tranh phổ với giọng nói | F12: Cả hai | G12: 4. Trộn nhiễu và mô phỏng khoang xe (sau TTS) | I12: Trộn sau khi có âm thanh sạch; ghi nguồn ồn và snr_actual_dB; dùng nhiều nguồn ồn và ồn đổi giữa câu. | J12: Trộn nhiễu giảm WER khoảng 5,1%, nhiễu cộng vang khoảng 6,6% (Ogun et al. 2025; Common Voice tiếng Anh, 50 giờ thật; cần kiểm chứng cho tiếng Việt). | K12: Che giọng khi nhạc có lời | L12: WER có/không ducking | M12: Cao | N12: Thu mẫu nhỏ làm mốc | O12: Không do câu quyết định
A13: 1. Nhiễu và âm thanh nền | B13: 1.3 Nguồn ồn từ bên trong khoang | C13: A08 | D13: Hành khách nói chuyện, trẻ em | E13: Số người; trẻ khóc hoặc la. Chỉ dẫn: Tiếng người cạnh tranh, khó lọc | F13: Cả hai | G13: 4. Trộn nhiễu và mô phỏng khoang xe (sau TTS) | I13: Trộn sau khi có âm thanh sạch; ghi nguồn ồn và snr_actual_dB; dùng nhiều nguồn ồn và ồn đổi giữa câu. | J13: Trộn nhiễu giảm WER khoảng 5,1%, nhiễu cộng vang khoảng 6,6% (Ogun et al. 2025; Common Voice tiếng Anh, 50 giờ thật; cần kiểm chứng cho tiếng Việt). | K13: Gây phân tâm, làm giảm độ rõ | L13: WER; đánh giá mức phân tâm | M13: Cao | N13: Thu mẫu nhỏ làm mốc | O13: Không do câu quyết định
A14: 1. Nhiễu và âm thanh nền | B14: 1.3 Nguồn ồn từ bên trong khoang | C14: A13 | D14: Âm báo của xe cạnh tranh với giọng trợ lý | E14: Chuông cảnh báo, xi-nhan, bíp lùi, nhắc dây an toàn, âm ADAS: ngắn, lặp, dải trung–cao | F14: Cả hai | G14: 4. Trộn nhiễu và mô phỏng khoang xe (sau TTS) | I14: Trộn sau khi có âm thanh sạch; ghi nguồn ồn và snr_actual_dB; dùng nhiều nguồn ồn và ồn đổi giữa câu. | J14: Chưa có bằng chứng đã đọc. | K14: Chồng lên thông báo, che từ quan trọng; thứ tự ưu tiên giữa âm báo và giọng chưa rõ | L14: WER đoạn bị chồng; tỷ lệ nghe được từ khóa | M14: Cao | N14: Đo trực tiếp | O14: Không do câu quyết định
A15: 1. Nhiễu và âm thanh nền | B15: 1.3 Nguồn ồn từ bên trong khoang | C15: A14 | D15: Người khác nói chồng lên lệnh người dùng | E15: Hành khách nói chen khi người lái ra lệnh; chồng lấn từng phần hoặc hoàn toàn | F15: Đầu vào (ASR) | G15: 4. Trộn nhiễu và mô phỏng khoang xe (sau TTS) | H15: 2. Chọn giọng và đoạn tham chiếu | I15: Cần giọng thứ hai: lấy từ cùng kho giọng clone, trộn ở nhiều mức chồng lấn. | J15: Chưa có bằng chứng đã đọc. | K15: Khác với nền tiếng người (babble): ở đây hai giọng rõ ràng cùng lúc, hệ thống có thể nhận nhầm người ra lệnh | L15: WER; tỷ lệ nhận đúng người ra lệnh | M15: Cao | N15: Không thu được, phải tạo | O15: Không do câu quyết định
A16: 1. Nhiễu và âm thanh nền | B16: 1.4 Tính chất thay đổi theo thời gian | C16: A11 | D16: Nhiều nguồn ồn cùng lúc | E16: Ví dụ gió + lốp + nhạc + quạt; ồn tổng tính theo năng lượng, không phải cộng mức dB | F16: Cả hai | G16: 4. Trộn nhiễu và mô phỏng khoang xe (sau TTS) | H16: 6. Chỉ để đánh giá | I16: Trộn sau khi có âm thanh sạch; ghi nguồn ồn và snr_actual_dB; dùng nhiều nguồn ồn và ồn đổi giữa câu. | J16: Trộn nhiễu giảm WER khoảng 5,1%, nhiễu cộng vang khoảng 6,6% (Ogun et al. 2025; Common Voice tiếng Anh, 50 giờ thật; cần kiểm chứng cho tiếng Việt). | K16: Cấu hình thực tế khó hơn từng nguồn riêng lẻ; model chỉ thử với một nguồn sẽ đánh giá quá lạc quan | L16: WER theo số nguồn ồn | M16: Cao | N16: Thu mẫu nhỏ làm mốc | O16: Không do câu quyết định
A17: 1. Nhiễu và âm thanh nền | B17: 1.4 Tính chất thay đổi theo thời gian | C17: A12 | D17: Ồn không dừng, đổi giữa câu | E17: Mở kính, vào hầm, đi qua cầu, còi bất chợt, tăng tốc khi đang đọc | F17: Cả hai | G17: 4. Trộn nhiễu và mô phỏng khoang xe (sau TTS) | I17: Trộn sau khi có âm thanh sạch; ghi nguồn ồn và snr_actual_dB; dùng nhiều nguồn ồn và ồn đổi giữa câu. | J17: Trộn nhiễu giảm WER khoảng 5,1%, nhiễu cộng vang khoảng 6,6% (Ogun et al. 2025; Common Voice tiếng Anh, 50 giờ thật; cần kiểm chứng cho tiếng Việt). | K17: SNR đổi giữa chừng: đầu câu rõ nhưng cuối câu bị che; ồn nền cố định che mất hiện tượng này | L17: WER theo đoạn đầu và đoạn cuối câu | M17: Cao | N17: Không thu được, phải tạo | O17: Không do câu quyết định
A18: 2. Khoang xe và thiết bị âm thanh | B18: 2.1 Hình học, vật liệu, vị trí nghe | C18: B01 | D18: Kích thước và vật liệu nội thất | E18: Sedan/SUV/MPV; da, vải, kính. Chỉ dẫn: Thời gian vang khác nhau theo xe | F18: Cả hai | G18: 4. Trộn nhiễu và mô phỏng khoang xe (sau TTS) | I18: Trộn sau khi có âm thanh sạch; ghi nguồn ồn và snr_actual_dB; dùng nhiều nguồn ồn và ồn đổi giữa câu. | J18: Trộn nhiễu giảm WER khoảng 5,1%, nhiễu cộng vang khoảng 6,6% (Ogun et al. 2025; Common Voice tiếng Anh, 50 giờ thật; cần kiểm chứng cho tiếng Việt). | K18: Vang làm nhòe âm tiết, đổi nhịp nghe | L18: WER; độ rõ (STOI) | M18: Trung bình | N18: Đo trực tiếp | O18: Không do câu quyết định
A19: 2. Khoang xe và thiết bị âm thanh | B19: 2.1 Hình học, vật liệu, vị trí nghe | C19: B03 | D19: Vị trí tai người nghe | E19: Ghế lái, ghế phụ, ghế sau. Chỉ dẫn: Mức và vang khác nhau theo ghế | F19: Đầu ra (TTS) | G19: Ngoài phạm vi ASR (phía loa hoặc hệ thống) | I19: Không đưa vào dữ liệu ASR; giữ cho đánh giá TTS sản phẩm (M5). | J19: Chưa có bằng chứng đã đọc. | K19: Người ngồi sau nghe kém hơn | L19: WER theo ghế | M19: Trung bình | N19: Đo trực tiếp | O19: Không do câu quyết định
A20: 2. Khoang xe và thiết bị âm thanh | B20: 2.1 Hình học, vật liệu, vị trí nghe | C20: B10 | D20: Điểm đo và hiệu chuẩn mức | E20: Mức ồn tại tai người nghe khác mức tại mic; cần ghi vị trí đo và hiệu chuẩn bằng máy đo SPL | F20: Cả hai | G20: 6. Chỉ để đánh giá | H20: 4. Trộn nhiễu và mô phỏng khoang xe (sau TTS) | I20: Đưa vào bộ đánh giá; không dùng làm điều khiển khi sinh. | J20: Chưa có bằng chứng đã đọc. | K20: Nếu mỗi nơi đo một điểm, các giá trị dB(A) và SNR không so sánh được với nhau; giá trị hiện trong file vẫn là chỉ dẫn chưa đo | L20: Sai số hiệu chuẩn (dB) | M20: Cao | N20: Đo trực tiếp | O20: Không do câu quyết định
A21: 2. Khoang xe và thiết bị âm thanh | B21: 2.2 Loa, mức phát, vùng phát, khử vọng | C21: B02 | D21: Vị trí và số lượng loa | E21: 4, 6, 8 loa trở lên; loa headrest. Chỉ dẫn: Phổ và hướng âm khác nhau | F21: Đầu ra (TTS) | G21: Ngoài phạm vi ASR (phía loa hoặc hệ thống) | I21: Không đưa vào dữ liệu ASR; giữ cho đánh giá TTS sản phẩm (M5). | J21: Chưa có bằng chứng đã đọc. | K21: Một số dải bị yếu hoặc nhấn quá mức | L21: Độ rõ; MOS | M21: Trung bình | N21: Đo trực tiếp | O21: Không do câu quyết định
A22: 2. Khoang xe và thiết bị âm thanh | B22: 2.2 Loa, mức phát, vùng phát, khử vọng | C22: B04 | D22: Mức phát và bù âm theo tốc độ | E22: Âm lượng mặc định; bù theo tốc độ. Chỉ dẫn: Phụ thuộc cấu hình hệ thống âm thanh xe | F22: Đầu ra (TTS) | G22: Ngoài phạm vi ASR (phía loa hoặc hệ thống) | I22: Không đưa vào dữ liệu ASR; giữ cho đánh giá TTS sản phẩm (M5). | J22: Chưa có bằng chứng đã đọc. | K22: TTS cần to hơn khi nền ồn tăng | L22: SNR tại tai; độ rõ | M22: Cao | N22: Đo trực tiếp | O22: Không do câu quyết định
A23: 2. Khoang xe và thiết bị âm thanh | B23: 2.2 Loa, mức phát, vùng phát, khử vọng | C23: B05 | D23: Tiếng vọng và ngắt lời (AEC, barge-in) | E23: Người dùng nói chen khi TTS đang phát. Chỉ dẫn: Tiếng TTS lọt vào mic | F23: Đầu vào (ASR) | G23: 5. Chuỗi xử lý đầu vào (sau trộn) | H23: Ngoài phạm vi ASR (phía loa hoặc hệ thống) | I23: Áp cùng chuỗi xử lý khi tạo dữ liệu và khi chạy thật. | J23: Chưa có bằng chứng đã đọc. | K23: Ảnh hưởng nhận dạng giọng nói và việc dừng TTS | L23: Tỷ lệ ngắt đúng; WER ASR | M23: Trung bình | N23: Thu mẫu nhỏ làm mốc | O23: Không do câu quyết định
A24: 2. Khoang xe và thiết bị âm thanh | B24: 2.2 Loa, mức phát, vùng phát, khử vọng | C24: B06 | D24: Vùng âm thanh (zone) | E24: Chỉ người lái; toàn khoang; riêng ghế sau. Chỉ dẫn: Thông báo gửi đúng vùng | F24: Đầu ra (TTS) | G24: Ngoài phạm vi ASR (phía loa hoặc hệ thống) | I24: Không đưa vào dữ liệu ASR; giữ cho đánh giá TTS sản phẩm (M5). | J24: Chưa có bằng chứng đã đọc. | K24: Lộ nội dung hoặc làm phiền người không liên quan | L24: Tỷ lệ phát đúng vùng | M24: Trung bình | N24: Đo trực tiếp | O24: Không do câu quyết định
A25: 2. Khoang xe và thiết bị âm thanh | B25: 2.2 Loa, mức phát, vùng phát, khử vọng | C25: B08 | D25: Méo và giới hạn công suất của loa | E25: Méo phi tuyến, bị cắt đỉnh (clipping) khi âm lượng cao; giới hạn của bộ khuếch đại | F25: Đầu ra (TTS) | G25: Ngoài phạm vi ASR (phía loa hoặc hệ thống) | I25: Không đưa vào dữ liệu ASR; giữ cho đánh giá TTS sản phẩm (M5). | J25: Chưa có bằng chứng đã đọc. | K25: TTS phát to hơn để thắng ồn nhưng bị méo, làm giảm độ rõ thay vì tăng | L25: THD+N; WER theo mức phát | M25: Trung bình | N25: Đo trực tiếp | O25: Không do câu quyết định
A26: 2. Khoang xe và thiết bị âm thanh | B26: 2.2 Loa, mức phát, vùng phát, khử vọng | C26: B09 | D26: EQ và chế độ âm thanh của xe | E26: Tăng bass, loudness, âm thanh vòm, các chế độ nhạc | F26: Đầu ra (TTS) | G26: Ngoài phạm vi ASR (phía loa hoặc hệ thống) | I26: Không đưa vào dữ liệu ASR; giữ cho đánh giá TTS sản phẩm (M5). | J26: Chưa có bằng chứng đã đọc. | K26: Đổi phổ giọng; nhấn bass che nguyên âm, giọng nam bị đục | L26: Độ rõ; MOS theo chế độ EQ | M26: Trung bình | N26: Đo trực tiếp | O26: Không do câu quyết định
A27: 2. Khoang xe và thiết bị âm thanh | B27: 2.3 Micro và thu đầu vào | C27: B07 | D27: Vị trí, số lượng và kiểu micro | E27: Micro trần, táp-lô; một mic hoặc mảng 2–4 mic; định hướng theo ghế (beamforming) | F27: Đầu vào (ASR) | G27: 4. Trộn nhiễu và mô phỏng khoang xe (sau TTS) | H27: 5. Chuỗi xử lý đầu vào (sau trộn) | I27: Trộn sau khi có âm thanh sạch; ghi nguồn ồn và snr_actual_dB; dùng nhiều nguồn ồn và ồn đổi giữa câu. | J27: Trộn nhiễu giảm WER khoảng 5,1%, nhiễu cộng vang khoảng 6,6% (Ogun et al. 2025; Common Voice tiếng Anh, 50 giờ thật; cần kiểm chứng cho tiếng Việt). | K27: Quyết định SNR của giọng người dùng và có nghe được hành khách ghế khác hay không | L27: WER theo ghế và theo cấu hình mic | M27: Cao | N27: Thu mẫu nhỏ làm mốc | O27: Không do câu quyết định
A28: 3. Chuỗi tín hiệu và hệ thống | B28: 3.1 Mã hóa, băng thông, đường truyền | C28: C01 | D28: Tần số lấy mẫu và băng thông | E28: 16 kHz; 22,05 kHz; 24 kHz; 44,1–48 kHz. Chỉ dẫn: Băng thông thấp mất thông tin ở dải cao | F28: Đầu ra (TTS) | G28: 5. Chuỗi xử lý đầu vào (sau trộn) | I28: Áp cùng chuỗi xử lý khi tạo dữ liệu và khi chạy thật. | J28: Chưa có bằng chứng đã đọc. | K28: Mất phụ âm xát, âm nghe nghẹt | L28: MOS; độ rõ | M28: Trung bình | N28: Không cần dữ liệu thu (tất định, văn bản hoặc đo hệ thống) | O28: Không do câu quyết định
A29: 3. Chuỗi tín hiệu và hệ thống | B29: 3.1 Mã hóa, băng thông, đường truyền | C29: C02 | D29: Bluetooth (HFP, A2DP) | E29: HFP băng hẹp (8 kHz) hoặc rộng (16 kHz); A2DP. Chỉ dẫn: Chất lượng giảm khi nén | F29: Cả hai | G29: 5. Chuỗi xử lý đầu vào (sau trộn) | I29: Áp cùng chuỗi xử lý khi tạo dữ liệu và khi chạy thật. | J29: Chưa có bằng chứng đã đọc. | K29: Mất chi tiết, tiếng rè, nghe kém | L29: WER qua Bluetooth | M29: Cao | N29: Không cần dữ liệu thu (tất định, văn bản hoặc đo hệ thống) | O29: Không do câu quyết định
A30: 3. Chuỗi tín hiệu và hệ thống | B30: 3.1 Mã hóa, băng thông, đường truyền | C30: C03 | D30: Chuẩn hóa độ lớn và nén động | E30: Mục tiêu độ lớn (LUFS); nén động (DRC). Chỉ dẫn: Cần ổn định giữa các câu và giữa các giọng | F30: Đầu ra (TTS) | G30: 5. Chuỗi xử lý đầu vào (sau trộn) | I30: Áp cùng chuỗi xử lý khi tạo dữ liệu và khi chạy thật. | J30: Chưa có bằng chứng đã đọc. | K30: Câu to nhỏ không đều gây khó chịu | L30: Độ lệch độ lớn giữa các câu | M30: Trung bình | N30: Không cần dữ liệu thu (tất định, văn bản hoặc đo hệ thống) | O30: Không do câu quyết định
A31: 3. Chuỗi tín hiệu và hệ thống | B31: 3.1 Mã hóa, băng thông, đường truyền | C31: C06 | D31: Chạy trên thiết bị và trên đám mây | E31: Mất mạng; lượng tử hóa; giới hạn bộ nhớ. Chỉ dẫn: Chất lượng có thể giảm khi nén mô hình | F31: Cả hai | G31: Ngoài phạm vi ASR (phía loa hoặc hệ thống) | I31: Không đưa vào dữ liệu ASR; giữ cho đánh giá TTS sản phẩm (M5). | J31: Chưa có bằng chứng đã đọc. | K31: Giảm chất lượng giọng; mất mạng giữa chừng | L31: MOS; WER; tỷ lệ phục vụ được ngoại tuyến | M31: Trung bình | N31: Không cần dữ liệu thu (tất định, văn bản hoặc đo hệ thống) | O31: Không do câu quyết định
A32: 3. Chuỗi tín hiệu và hệ thống | B32: 3.1 Mã hóa, băng thông, đường truyền | C32: C09 | D32: Codec cuộc gọi và kết nối điện thoại | E32: CarPlay, Android Auto, cuộc gọi VoIP; băng hẹp hoặc băng rộng | F32: Cả hai | G32: 5. Chuỗi xử lý đầu vào (sau trộn) | I32: Áp cùng chuỗi xử lý khi tạo dữ liệu và khi chạy thật. | J32: Chưa có bằng chứng đã đọc. | K32: Giọng bị nén theo codec của cuộc gọi, khác với Bluetooth phát nhạc | L32: WER qua codec; độ dễ nghe | M32: Trung bình | N32: Không cần dữ liệu thu (tất định, văn bản hoặc đo hệ thống) | O32: Không do câu quyết định
A33: 3. Chuỗi tín hiệu và hệ thống | B33: 3.2 Độ trễ và điều phối thông báo | C33: C04 | D33: Độ trễ và phát luồng | E33: Thời gian đến âm đầu (TTFA); kích thước đoạn. Chỉ dẫn: Cảnh báo cần trễ rất thấp | F33: Đầu ra (TTS) | G33: Ngoài phạm vi ASR (phía loa hoặc hệ thống) | I33: Không đưa vào dữ liệu ASR; giữ cho đánh giá TTS sản phẩm (M5). | J33: Chưa có bằng chứng đã đọc. | K33: Trễ làm mất giá trị của cảnh báo và dẫn đường | L33: TTFA (p50, p95) | M33: Cao | N33: Không cần dữ liệu thu (tất định, văn bản hoặc đo hệ thống) | O33: Không do câu quyết định
A34: 3. Chuỗi tín hiệu và hệ thống | B34: 3.2 Độ trễ và điều phối thông báo | C34: C05 | D34: Ưu tiên và ngắt thông báo | E34: Cảnh báo > dẫn đường > giải trí. Chỉ dẫn: Quy tắc xếp hàng và ngắt | F34: Đầu ra (TTS) | G34: Ngoài phạm vi ASR (phía loa hoặc hệ thống) | I34: Không đưa vào dữ liệu ASR; giữ cho đánh giá TTS sản phẩm (M5). | J34: Chưa có bằng chứng đã đọc. | K34: Thông báo quan trọng bị cắt hoặc chờ | L34: Tỷ lệ phát đúng thứ tự | M34: Cao | N34: Không cần dữ liệu thu (tất định, văn bản hoặc đo hệ thống) | O34: Không do câu quyết định
A35: 3. Chuỗi tín hiệu và hệ thống | B35: 3.3 Xử lý đầu vào và mạng | C35: C07 | D35: Khử ồn, AGC và khử vọng ở đầu vào | E35: Bộ lọc nhiễu, tự động chỉnh độ lợi, khử vọng chạy trước bộ nhận dạng | F35: Đầu vào (ASR) | G35: 5. Chuỗi xử lý đầu vào (sau trộn) | I35: Áp cùng chuỗi xử lý khi tạo dữ liệu và khi chạy thật. | J35: Chưa có bằng chứng đã đọc. | K35: Có thể làm méo giọng người nói hoặc cắt mất đầu câu; model ASR cần quen với âm thanh sau xử lý | L35: WER trước và sau xử lý | M35: Cao | N35: Thu mẫu nhỏ làm mốc | O35: Không do câu quyết định
A36: 3. Chuỗi tín hiệu và hệ thống | B36: 3.3 Xử lý đầu vào và mạng | C36: C08 | D36: Mạng không ổn định khi TTS chạy đám mây | E36: Trễ biến động (jitter), mất gói, chờ đệm, mất mạng giữa câu | F36: Đầu ra (TTS) | G36: Ngoài phạm vi ASR (phía loa hoặc hệ thống) | I36: Không đưa vào dữ liệu ASR; giữ cho đánh giá TTS sản phẩm (M5). | J36: Chưa có bằng chứng đã đọc. | K36: Giọng bị ngắt quãng hoặc trễ; cảnh báo đến muộn | L36: Tỷ lệ ngắt quãng; TTFA p95 | M36: Cao | N36: Không cần dữ liệu thu (tất định, văn bản hoặc đo hệ thống) | O36: Không do câu quyết định
A37: 4. Người nói | B37: 4.1 Sinh lý và tần số giọng | C37: S11 | D37: Giới tính | E37: Nam / Nữ | F37: Cả hai | G37: 2. Chọn giọng và đoạn tham chiếu | I37: Đặt hạn ngạch người nói ở Chi_tieu; chọn đoạn tham chiếu theo hồ sơ ở Ho_so_nguoi_noi. | J37: Thêm người nói chỉ giảm WER khoảng 2%; khoảng 50–100 người nói là đủ (Ogun et al.; Versatile TTS). | K37: Quyết định dải F0 và vị trí formant; chọn giọng TTS nên hợp ngữ cảnh người nghe | L37: Tỷ lệ mẫu theo giới | M37: Cao | N37: Thu mẫu nhỏ làm mốc | O37: Không do câu quyết định
A38: 4. Người nói | B38: 4.1 Sinh lý và tần số giọng | C38: S12 | D38: Nhóm tuổi | E38: Trẻ em; thiếu niên; thanh niên; trung niên; cao tuổi | F38: Đầu vào (ASR) | G38: 2. Chọn giọng và đoạn tham chiếu | I38: Trẻ em và người cao tuổi: cần nguồn giọng thật có đồng ý. Không tạo từ giọng người lớn bằng dịch cao độ (nhận định của mình, chưa kiểm chứng); nếu không có nguồn thì để ngoài phạm vi. | J38: Thêm người nói chỉ giảm WER khoảng 2%; khoảng 50–100 người nói là đủ (Ogun et al.; Versatile TTS). | K38: Trẻ em có F0 cao và phát âm chưa ổn định; người cao tuổi giọng run, tốc độ chậm, nhận dạng kém hơn | L38: Tỷ lệ mẫu theo nhóm tuổi; WER theo nhóm tuổi | M38: Trung bình | N38: Thu mẫu nhỏ làm mốc | O38: Không do câu quyết định
A39: 4. Người nói | B39: 4.1 Sinh lý và tần số giọng | C39: S13 | D39: Tần số giọng trung bình (F0) | E39: Dải Thấp / Trung bình / Cao / Rất cao (ngưỡng chỉ dẫn ở sheet Ho_so_nguoi_noi) | F39: Cả hai | G39: 2. Chọn giọng và đoạn tham chiếu | I39: Chọn người nói có F0 tự nhiên khác nhau; không dịch cao độ để tăng độ phủ F0. | J39: Dịch cao độ và đổi giọng để tăng đa dạng người nói không hiệu quả (Ogun et al.: WER tệ hơn 0,8% và 2,2%). | K39: F0 thấp dễ bị tiếng ồn dải thấp của lốp, động cơ che; F0 cao ít bị che nhưng nhạy với nhiễu quạt và gió ở dải trung–cao | L39: F0 trung bình đo được so với dải khai báo | M39: Cao | N39: Thu mẫu nhỏ làm mốc | O39: Không do câu quyết định
A40: 4. Người nói | B40: 4.1 Sinh lý và tần số giọng | C40: S14 | D40: Khoảng biến thiên F0 (cao độ trong câu) | E40: Khoảng F0 theo nửa cung hoặc Hz; độ lệch chuẩn F0 | F40: Cả hai | G40: 3. Điều khiển khi sinh TTS | H40: 2. Chọn giọng và đoạn tham chiếu | I40: Điều khiển khi sinh (tốc độ, phong cách, tham chiếu) rồi đo lại bằng căn chỉnh hoặc nghe kiểm. | J40: Thêm người nói chỉ giảm WER khoảng 2%; khoảng 50–100 người nói là đủ (Ogun et al.; Versatile TTS). | K40: Tiếng Việt có 6 thanh điệu nên đường nét F0 mang nghĩa; nhiễu che đường nét làm nghe nhầm thanh | L40: Khoảng F0 (nửa cung) so với giọng tham chiếu | M40: Trung bình | N40: Thu mẫu nhỏ làm mốc | O40: Không do câu quyết định
...

Sheet Buoc_xu_ly
A1: Số yếu tố theo bước xử lý
A2: Đếm từ sheet Yeu_to. Bước 1 là phần bộ mẫu câu phải đáp ứng trực tiếp.
A3: Bước xử lý | B3: Làm gì | C3: Số yếu tố (bước chính) | D3: Số yếu tố (bước phụ)
A4: 1. Thiết kế câu (văn bản) | B4: Quyết định bằng chính câu: mẫu câu, khe thông tin, từ vựng vùng, số, tên riêng, độ dài. Đây là phần bộ mẫu câu phải đáp ứng trực tiếp. | C4: =COUNTIF(Yeu_to!$G$4:$G$74,A4) -> 15 | D4: =COUNTIF(Yeu_to!$H$4:$H$74,A4) -> 2
A5: 2. Chọn giọng và đoạn tham chiếu | B5: Quyết định bằng người nói được clone: vùng, giới, F0, chất giọng. Xử lý bằng hạn ngạch người nói và chọn đoạn tham chiếu, không bằng câu. | C5: =COUNTIF(Yeu_to!$G$4:$G$74,A5) -> 11 | D5: =COUNTIF(Yeu_to!$H$4:$H$74,A5) -> 3
A6: 3. Điều khiển khi sinh TTS | B6: Điều khiển lúc sinh âm thanh: tốc độ, phong cách, ngắt nghỉ, cảm xúc. Kết quả phải đo lại sau khi sinh. | C6: =COUNTIF(Yeu_to!$G$4:$G$74,A6) -> 7 | D6: =COUNTIF(Yeu_to!$H$4:$H$74,A6) -> 3
A7: 4. Trộn nhiễu và mô phỏng khoang xe (sau TTS) | B7: Thêm sau khi TTS đã sinh âm thanh sạch: tiếng ồn, vang khoang xe, mức giọng so với ồn, vị trí mic. | C7: =COUNTIF(Yeu_to!$G$4:$G$74,A7) -> 18 | D7: =COUNTIF(Yeu_to!$H$4:$H$74,A7) -> 2
A8: 5. Chuỗi xử lý đầu vào (sau trộn) | B8: Chuỗi xử lý giữa mic và bộ nhận dạng: tần số lấy mẫu, codec, khử ồn, AGC. Dùng cùng chuỗi khi tạo dữ liệu và khi chạy thật. | C8: =COUNTIF(Yeu_to!$G$4:$G$74,A8) -> 6 | D8: =COUNTIF(Yeu_to!$H$4:$H$74,A8) -> 1
A9: 6. Chỉ để đánh giá | B9: Không điều khiển được khi sinh; chỉ có thể đo ở bộ đánh giá. | C9: =COUNTIF(Yeu_to!$G$4:$G$74,A9) -> 1 | D9: =COUNTIF(Yeu_to!$H$4:$H$74,A9) -> 4
A10: Tinh chỉnh TTS (tùy chọn) | B10: Nếu zero-shot không giữ được giọng vùng thì tinh chỉnh TTS trên giọng thật có nhãn vùng. | C10: =COUNTIF(Yeu_to!$G$4:$G$74,A10) -> 0 | D10: =COUNTIF(Yeu_to!$H$4:$H$74,A10) -> 1
A11: Ngoài phạm vi ASR (phía loa hoặc hệ thống) | B11: Thuộc đường phát ra loa hoặc hệ thống trợ lý, không ảnh hưởng dữ liệu huấn luyện ASR; giữ lại cho giai đoạn đánh giá TTS sản phẩm (mục đích M5). | C11: =COUNTIF(Yeu_to!$G$4:$G$74,A11) -> 13 | D11: =COUNTIF(Yeu_to!$H$4:$H$74,A11) -> 1
A12: Tổng | C12: =SUM(C4:C11) -> 71 | D12: =SUM(D4:D11) -> 17
A13: Kiểm tra: tổng bước chính bằng số yếu tố | C13: =IF(C12=COUNTA(Yeu_to!$C$4:$C$74),"Khớp","Lệch") -> Khớp

Sheet Ma_tran
A1: Ma trận case × yếu tố
A2: ● = case cần yếu tố này (trọng yếu); ○ = có xuất hiện. Hàng 5 cho bước xử lý chính; chỉ yếu tố thuộc bước 1 được phủ bằng câu, hàng 21 đếm số câu mẫu phủ.
A3: Mã case | B3: Tên case | C3: Mục đích chính | D3: E02 | E3: E03 | F3: E04 | G3: E05 | H3: E06 | I3: E07 | J3: E08 | K3: D01 | L3: D03 | M3: S21 | N3: S22 | O3: S23 | P3: S24 | Q3: S33 | R3: S51 | S3: S52 | T3: S53 | U3: S54 | V3: S55 | W3: S12 | X3: A07 | Y3: A14 | Z3: Số yếu tố ● | AA3: Số câu mẫu M1, M2
A4: Tên yếu tố | D4: =INDEX(Yeu_to!$D$4:$D$74,MATCH(D$3,Yeu_to!$C$4:$C$74,0)) -> Thanh điệu dưới nhiễu | E4: =INDEX(Yeu_to!$D$4:$D$74,MATCH(E$3,Yeu_to!$C$4:$C$74,0)) -> Chuẩn hóa số, giờ, ngày, tiền, đơn vị | F4: =INDEX(Yeu_to!$D$4:$D$74,MATCH(F$3,Yeu_to!$C$4:$C$74,0)) -> Tên đường, địa danh, địa chỉ | G4: =INDEX(Yeu_to!$D$4:$D$74,MATCH(G$3,Yeu_to!$C$4:$C$74,0)) -> Từ mượn và chuyển mã Anh–Việt | H4: =INDEX(Yeu_to!$D$4:$D$74,MATCH(H$3,Yeu_to!$C$4:$C$74,0)) -> Xưng hô và từ đệm | I4: =INDEX(Yeu_to!$D$4:$D$74,MATCH(I$3,Yeu_to!$C$4:$C$74,0)) -> Viết tắt và ký hiệu | J4: =INDEX(Yeu_to!$D$4:$D$74,MATCH(J$3,Yeu_to!$C$4:$C$74,0)) -> Độ dài câu và ngắt nghỉ | K4: =INDEX(Yeu_to!$D$4:$D$74,MATCH(K$3,Yeu_to!$C$4:$C$74,0)) -> Tải nhận thức của người lái | ... Y4: =INDEX(Yeu_to!$D$4:$D$74,MATCH(Y$3,Yeu_to!$C$4:$C$74,0)) -> Người khác nói chồng lên lệnh người dùng
A5: Bước xử lý chính | D5: =INDEX(Yeu_to!$G$4:$G$74,MATCH(D$3,Yeu_to!$C$4:$C$74,0)) -> 1. Thiết kế câu (văn bản) | E5: =INDEX(Yeu_to!$G$4:$G$74,MATCH(E$3,Yeu_to!$C$4:$C$74,0)) -> 1. Thiết kế câu (văn bản) | F5: =INDEX(Yeu_to!$G$4:$G$74,MATCH(F$3,Yeu_to!$C$4:$C$74,0)) -> 1. Thiết kế câu (văn bản) | G5: =INDEX(Yeu_to!$G$4:$G$74,MATCH(G$3,Yeu_to!$C$4:$C$74,0)) -> 1. Thiết kế câu (văn bản) | H5: =INDEX(Yeu_to!$G$4:$G$74,MATCH(H$3,Yeu_to!$C$4:$C$74,0)) -> 1. Thiết kế câu (văn bản) | I5: =INDEX(Yeu_to!$G$4:$G$74,MATCH(I$3,Yeu_to!$C$4:$C$74,0)) -> 1. Thiết kế câu (văn bản) | J5: =INDEX(Yeu_to!$G$4:$G$74,MATCH(J$3,Yeu_to!$C$4:$C$74,0)) -> 1. Thiết kế câu (văn bản) | K5: =INDEX(Yeu_to!$G$4:$G$74,MATCH(K$3,Yeu_to!$C$4:$C$74,0)) -> 1. Thiết kế câu (văn bản) | ... Y5: =INDEX(Yeu_to!$G$4:$G$74,MATCH(Y$3,Yeu_to!$C$4:$C$74,0)) -> 4. Trộn nhiễu và mô phỏng khoang xe (sau TTS)
A6: CS01 | B6: =INDEX(Case_study!$B$4:$B$15,MATCH(A6,Case_study!$A$4:$A$15,0)) -> Dẫn đường | C6: =INDEX(Case_study!$D$4:$D$15,MATCH(A6,Case_study!$A$4:$A$15,0)) -> M1 | E6: ● | F6: ● | G6: ○ | I6: ○ | J6: ○ | K6: ● | O6: ○ | Q6: ○ | R6: ● | T6: ○ | U6: ● | Z6: =COUNTIF(D6:Y6,"●") -> 5 | AA6: =COUNTIFS(Mau_cau!$C$4:$C$300,A6,Mau_cau!$B$4:$B$300,"<>M4") -> 8
A7: CS02 | B7: =INDEX(Case_study!$B$4:$B$15,MATCH(A7,Case_study!$A$4:$A$15,0)) -> Cảnh báo an toàn (ADAS) | C7: =INDEX(Case_study!$D$4:$D$15,MATCH(A7,Case_study!$A$4:$A$15,0)) -> M5 | J7: ● | K7: ● | L7: ● | M7: ● | N7: ○ | O7: ● | Z7: =COUNTIF(D7:Y7,"●") -> 5 | AA7: =COUNTIFS(Mau_cau!$C$4:$C$300,A7,Mau_cau!$B$4:$B$300,"<>M4") -> 2
A8: CS03 | B8: =INDEX(Case_study!$B$4:$B$15,MATCH(A8,Case_study!$A$4:$A$15,0)) -> Điều khiển xe | C8: =INDEX(Case_study!$D$4:$D$15,MATCH(A8,Case_study!$A$4:$A$15,0)) -> M1 | D8: ● | E8: ● | G8: ○ | H8: ○ | J8: ○ | R8: ● | S8: ○ | V8: ● | Y8: ○ | Z8: =COUNTIF(D8:Y8,"●") -> 4 | AA8: =COUNTIFS(Mau_cau!$C$4:$C$300,A8,Mau_cau!$B$4:$B$300,"<>M4") -> 9
A9: CS04 | B9: =INDEX(Case_study!$B$4:$B$15,MATCH(A9,Case_study!$A$4:$A$15,0)) -> Giải trí (nhạc, radio) | C9: =INDEX(Case_study!$D$4:$D$15,MATCH(A9,Case_study!$A$4:$A$15,0)) -> M1 | E9: ○ | G9: ● | I9: ○ | Q9: ○ | V9: ● | X9: ● | Y9: ○ | Z9: =COUNTIF(D9:Y9,"●") -> 3 | AA9: =COUNTIFS(Mau_cau!$C$4:$C$300,A9,Mau_cau!$B$4:$B$300,"<>M4") -> 5
A10: CS05 | B10: =INDEX(Case_study!$B$4:$B$15,MATCH(A10,Case_study!$A$4:$A$15,0)) -> Điện thoại và tin nhắn | C10: =INDEX(Case_study!$D$4:$D$15,MATCH(A10,Case_study!$A$4:$A$15,0)) -> M1 | E10: ● | F10: ○ | H10: ● | S10: ● | T10: ● | Y10: ● | Z10: =COUNTIF(D10:Y10,"●") -> 5 | AA10: =COUNTIFS(Mau_cau!$C$4:$C$300,A10,Mau_cau!$B$4:$B$300,"<>M4") -> 6
A11: CS06 | B11: =INDEX(Case_study!$B$4:$B$15,MATCH(A11,Case_study!$A$4:$A$15,0)) -> Trạng thái xe và bảo dưỡng | C11: =INDEX(Case_study!$D$4:$D$15,MATCH(A11,Case_study!$A$4:$A$15,0)) -> M1 | E11: ● | I11: ● | J11: ○ | K11: ○ | Z11: =COUNTIF(D11:Y11,"●") -> 2 | AA11: =COUNTIFS(Mau_cau!$C$4:$C$300,A11,Mau_cau!$B$4:$B$300,"<>M4") -> 3
A12: CS07 | B12: =INDEX(Case_study!$B$4:$B$15,MATCH(A12,Case_study!$A$4:$A$15,0)) -> Sạc xe điện và trạm nhiên liệu | C12: =INDEX(Case_study!$D$4:$D$15,MATCH(A12,Case_study!$A$4:$A$15,0)) -> M1 | E12: ● | I12: ● | J12: ○ | T12: ● | Z12: =COUNTIF(D12:Y12,"●") -> 3 | AA12: =COUNTIFS(Mau_cau!$C$4:$C$300,A12,Mau_cau!$B$4:$B$300,"<>M4") -> 4
A13: CS08 | B13: =INDEX(Case_study!$B$4:$B$15,MATCH(A13,Case_study!$A$4:$A$15,0)) -> Giao thông và thời tiết | C13: =INDEX(Case_study!$D$4:$D$15,MATCH(A13,Case_study!$A$4:$A$15,0)) -> M1 | E13: ● | F13: ● | J13: ○ | K13: ○ | R13: ○ | Z13: =COUNTIF(D13:Y13,"●") -> 2 | AA13: =COUNTIFS(Mau_cau!$C$4:$C$300,A13,Mau_cau!$B$4:$B$300,"<>M4") -> 4
A14: CS09 | B14: =INDEX(Case_study!$B$4:$B$15,MATCH(A14,Case_study!$A$4:$A$15,0)) -> Khẩn cấp và cứu hộ | C14: =INDEX(Case_study!$D$4:$D$15,MATCH(A14,Case_study!$A$4:$A$15,0)) -> M1 | J14: ● | K14: ● | L14: ● | M14: ● | N14: ○ | O14: ● | P14: ● | Z14: =COUNTIF(D14:Y14,"●") -> 6 | AA14: =COUNTIFS(Mau_cau!$C$4:$C$300,A14,Mau_cau!$B$4:$B$300,"<>M4") -> 4
A15: CS10 | B15: =INDEX(Case_study!$B$4:$B$15,MATCH(A15,Case_study!$A$4:$A$15,0)) -> Hội thoại và gợi ý chủ động | C15: =INDEX(Case_study!$D$4:$D$15,MATCH(A15,Case_study!$A$4:$A$15,0)) -> M1 | E15: ○ | G15: ● | H15: ○ | J15: ● | O15: ○ | Q15: ● | V15: ● | Z15: =COUNTIF(D15:Y15,"●") -> 4 | AA15: =COUNTIFS(Mau_cau!$C$4:$C$300,A15,Mau_cau!$B$4:$B$300,"<>M4") -> 5
A16: CS11 | B16: =INDEX(Case_study!$B$4:$B$15,MATCH(A16,Case_study!$A$4:$A$15,0)) -> Hành khách và trẻ em | C16: =INDEX(Case_study!$D$4:$D$15,MATCH(A16,Case_study!$A$4:$A$15,0)) -> M1 | H16: ○ | M16: ○ | W16: ● | Y16: ● | Z16: =COUNTIF(D16:Y16,"●") -> 2 | AA16: =COUNTIFS(Mau_cau!$C$4:$C$300,A16,Mau_cau!$B$4:$B$300,"<>M4") -> 3
A17: CS12 | B17: =INDEX(Case_study!$B$4:$B$15,MATCH(A17,Case_study!$A$4:$A$15,0)) -> Lỗi, làm rõ và ngoại tuyến | C17: =INDEX(Case_study!$D$4:$D$15,MATCH(A17,Case_study!$A$4:$A$15,0)) -> M2 | H17: ● | J17: ● | O17: ● | Q17: ● | R17: ○ | Z17: =COUNTIF(D17:Y17,"●") -> 4 | AA17: =COUNTIFS(Mau_cau!$C$4:$C$300,A17,Mau_cau!$B$4:$B$300,"<>M4") -> 12
A19: Số case cần (●) | D19: =COUNTIF(D6:D17,"●") -> 1 | E19: =COUNTIF(E6:E17,"●") -> 6 | F19: =COUNTIF(F6:F17,"●") -> 2 | G19: =COUNTIF(G6:G17,"●") -> 2 | H19: =COUNTIF(H6:H17,"●") -> 2 | I19: =COUNTIF(I6:I17,"●") -> 2 | J19: =COUNTIF(J6:J17,"●") -> 4 | K19: =COUNTIF(K6:K17,"●") -> 3 | ... Y19: =COUNTIF(Y6:Y17,"●") -> 2
A20: Số câu mẫu phủ | D20: =IF(LEFT(D$5,1)="1",COUNTIF(Mau_cau!$N$4:$N$300,"*"&D$3&"*"),"—") -> 8 | E20: =IF(LEFT(E$5,1)="1",COUNTIF(Mau_cau!$N$4:$N$300,"*"&E$3&"*"),"—") -> 21 | F20: =IF(LEFT(F$5,1)="1",COUNTIF(Mau_cau!$N$4:$N$300,"*"&F$3&"*"),"—") -> 6 | G20: =IF(LEFT(G$5,1)="1",COUNTIF(Mau_cau!$N$4:$N$300,"*"&G$3&"*"),"—") -> 3 | H20: =IF(LEFT(H$5,1)="1",COUNTIF(Mau_cau!$N$4:$N$300,"*"&H$3&"*"),"—") -> 5 | I20: =IF(LEFT(I$5,1)="1",COUNTIF(Mau_cau!$N$4:$N$300,"*"&I$3&"*"),"—") -> 4 | J20: =IF(LEFT(J$5,1)="1",COUNTIF(Mau_cau!$N$4:$N$300,"*"&J$3&"*"),"—") -> 29 | K20: =IF(LEFT(K$5,1)="1",COUNTIF(Mau_cau!$N$4:$N$300,"*"&K$3&"*"),"—") -> 1 | ... Y20: =IF(LEFT(Y$5,1)="1",COUNTIF(Mau_cau!$N$4:$N$300,"*"&Y$3&"*"),"—") -> —

Sheet Mau_khung
A1: Mẫu câu × khe thông tin
A2: Số giá trị mỗi khe là mục tiêu cần liệt kê (ô vàng sửa được), không phải danh sách đã có. Sức chứa là tích tối đa; khe phụ thuộc nhau thì thực tế thấp hơn. Diễn đạt lại bằng LLM và người duyệt sẽ nhân thêm.
A3: Mã | B3: Case | C3: Ý định | D3: Mẫu câu | E3: Khe 1 | F3: Giá trị ví dụ khe 1 | G3: Số giá trị mục tiêu khe 1 | H3: Khe 2 | I3: Giá trị ví dụ khe 2 | J3: Số giá trị mục tiêu khe 2 | K3: Khe 3 | L3: Giá trị ví dụ khe 3 | M3: Số giá trị mục tiêu khe 3 | N3: Sức chứa tổ hợp | O3: Biến thể vùng | P3: Yếu tố (mã) | Q3: Ghi chú
A4: T01 | B4: CS01 | C4: dẫn đường đến địa chỉ | D4: {động từ} đến {đích} | E4: động từ | F4: Dẫn đường; Chỉ đường tới; Đưa tôi đến | G4: 4 | H4: đích | I4: số 15 ngõ 28 Chùa Bộc; hẻm 28 đường Nguyễn Văn Cừ; sân bay Nội Bài; bệnh viện Chợ Rẫy; Huế | J4: 300 | N4: =G4*IF(J4="",1,J4)*IF(M4="",1,M4) -> 1200 | O4: ngõ/hẻm theo vùng của địa chỉ | P4: E03; E04; S51; S54 | Q4: Danh sách đích lấy từ dữ liệu bản đồ (OpenStreetMap, ODbL, cần ghi nguồn) kèm cách gọi quen của người địa phương.
A5: T02 | B5: CS01 | C5: hỏi khoảng cách hoặc thời gian | D5: {hỏi} đến {đích} | E5: hỏi | F5: Còn bao xa; Mất bao lâu; Mấy giờ thì tới | G5: 5 | H5: đích | I5: Huế; Đà Nẵng; nhà; cơ quan | J5: 300 | N5: =G5*IF(J5="",1,J5)*IF(M5="",1,M5) -> 1500 | P5: E04; E08; S33
A6: T03 | B6: CS01 | C6: tìm đường tránh | D6: Tìm đường khác tránh {trở ngại} | E6: trở ngại | F6: kẹt xe (Nam); tắc đường (Bắc); công trình; ngập nước | G6: 8 | N6: =G6*IF(J6="",1,J6)*IF(M6="",1,M6) -> 8 | O6: kẹt xe/tắc đường | P6: S51
A7: T04 | B7: CS03 | C7: đặt nhiệt độ | D7: Đặt nhiệt độ {vị trí} {số} độ | E7: vị trí | F7: ghế lái; ghế phụ; khoang sau | G7: 3 | H7: số | I7: 18; 22; 24; 28 | J7: 11 | N7: =G7*IF(J7="",1,J7)*IF(M7="",1,M7) -> 33 | P7: E03; E02
A8: T05 | B8: CS03 | C8: hạ kính | D8: Hạ {kính} {bên} xuống {mức} | E8: kính | F8: kính (Bắc); kiếng (Nam) | G8: 2 | H8: bên | I8: bên lái; bên phụ; sau trái; sau phải | J8: 4 | K8: mức | L8: một nửa; hoàn toàn; một chút | M8: 3 | N8: =G8*IF(J8="",1,J8)*IF(M8="",1,M8) -> 24 | O8: kính/kiếng; thêm nha/nhé | P8: S51; S52; E02
A9: T06 | B9: CS03 | C9: bật điều hòa | D9: Bật {điều hòa} {số} độ | E9: điều hòa | F9: điều hòa (Bắc); máy lạnh (Nam); air-con | G9: 3 | H9: số | I9: 16; 19; 22; 26 | J9: 11 | N9: =G9*IF(J9="",1,J9)*IF(M9="",1,M9) -> 33 | O9: điều hòa/máy lạnh | P9: E03; S51; S55
A10: T07 | B10: CS04 | C10: mở nhạc | D10: Mở {loại} {tên} | E10: loại | F10: bài; danh sách nhạc; podcast | G10: 3 | H10: tên | I10: Chill cuối tuần; nhạc thiếu nhi | J10: 100 | N10: =G10*IF(J10="",1,J10)*IF(M10="",1,M10) -> 300 | P10: E05; A07 | Q10: Tên lấy từ kho nhạc; kiểm bản quyền nếu đưa lời bài hát.
A11: T08 | B11: CS04 | C11: chuyển kênh | D11: Chuyển sang kênh {kênh}, {tần số} | E11: kênh | F11: VOV Giao thông; VOV 3 | G11: 10 | H11: tần số | I11: FM 91 MHz; FM 102,7 MHz | J11: 10 | N11: =G11*IF(J11="",1,J11)*IF(M11="",1,M11) -> 100 | P11: E03; E07; E05
A12: T09 | B12: CS05 | C12: gọi | D12: Gọi cho {người} | E12: người | F12: anh Minh; chị Lan; mạ (Trung); má (Nam) | G12: 100 | N12: =G12*IF(J12="",1,J12)*IF(M12="",1,M12) -> 100 | O12: xưng hô mạ/má/mẹ | P12: E06; S52 | Q12: Tên người dùng tên phổ biến, không dùng tên người có thật.
A13: T10 | B13: CS05 | C13: gọi theo số | D13: Gọi số {số điện thoại} | E13: số điện thoại | F13: 0912 345 678; 0903 456 789 | G13: 200 | N13: =G13*IF(J13="",1,J13)*IF(M13="",1,M13) -> 200 | P13: E03; S53
A14: T11 | B14: CS06 | C14: hỏi trạng thái xe | D14: {vật} {bộ phận} {hỏi} | E14: vật | F14: Áp suất lốp; Nhiên liệu; Lịch bảo dưỡng | G14: 4 | H14: bộ phận | I14: trước bên phải; sau bên trái | J14: 4 | K14: hỏi | L14: bao nhiêu; còn bao nhiêu | M14: 3 | N14: =G14*IF(J14="",1,J14)*IF(M14="",1,M14) -> 48 | O14: bao giờ/khi nào | P14: E03; E07
A15: T12 | B15: CS07 | C15: hỏi sạc | D15: Sạc từ {x} lên {y} phần trăm mất bao lâu | E15: x | F15: 20; 35; 50 | G15: 8 | H15: y | I15: 80; 90; 100 | J15: 4 | N15: =G15*IF(J15="",1,J15)*IF(M15="",1,M15) -> 32 | P15: E03; E07
A16: T13 | B16: CS08 | C16: hỏi thời tiết | D16: Hôm nay {thành phố} có {hiện tượng} không | E16: thành phố | F16: Hà Nội; Đà Nẵng; Huế; Cần Thơ | G16: 63 | H16: hiện tượng | I16: mưa; nắng; ngập | J16: 4 | N16: =G16*IF(J16="",1,J16)*IF(M16="",1,M16) -> 252 | P16: E04
A17: T14 | B17: CS09 | C17: gọi khẩn cấp | D17: Gọi {dịch vụ} | E17: dịch vụ | F17: cấp cứu 115; cứu hộ giao thông | G17: 4 | N17: =G17*IF(J17="",1,J17)*IF(M17="",1,M17) -> 4 | P17: D03; S23 | Q17: Trạng thái giọng căng thẳng; ít mẫu.
A18: T15 | B18: CS10 | C18: nhắc việc | D18: Nhắc tôi {việc} {lúc} | E18: việc | F18: mua sữa; họp; đón con | G18: 100 | H18: lúc | I18: lúc chín giờ sáng mai; khi đi ngang siêu thị | J18: 20 | N18: =G18*IF(J18="",1,J18)*IF(M18="",1,M18) -> 2000 | P18: E03; E08
A19: T16 | B19: CS10 | C19: hỏi quán gần đây | D19: Gần đây có {quán} nào có chỗ {đỗ} xe không | E19: quán | F19: quán cà phê; nhà hàng; trạm sạc | G19: 10 | H19: đỗ | I19: đỗ (Bắc); đậu (Nam) | J19: 2 | N19: =G19*IF(J19="",1,J19)*IF(M19="",1,M19) -> 20 | O19: đỗ/đậu | P19: S51; E08
A20: T17 | B20: CS12 | C20: trả lời ngắn | D20: {trả lời} | E20: trả lời | F20: Có; Không; Hủy; Cái thứ hai; Hai | G20: 40 | N20: =G20*IF(J20="",1,J20)*IF(M20="",1,M20) -> 40 | O20: vâng/dạ | P20: E08; S33; S52 | Q20: Câu rất ngắn.
A21: T18 | B21: CS12 | C21: sửa lệnh | D21: Không phải, ý tôi là {lệnh đúng} | E21: lệnh đúng | F21: gọi anh Hùng Trần; đi đường khác | G21: 100 | N21: =G21*IF(J21="",1,J21)*IF(M21="",1,M21) -> 100 | P21: S23; E06

Sheet Mau_cau
A1: Câu mẫu của người dùng (M1, M2) và câu chẩn đoán (M4)
A2: Cột xanh lá tự tính (số âm tiết = số từ cách nhau bởi dấu cách; thời lượng = âm tiết / tốc độ ở Tong_quan!B40). M3 chưa có dòng vì chưa chọn bộ thật. Ví dụ từ vùng cần người bản ngữ duyệt.
A3: sample_id | B3: purpose | C3: case_id | D3: case_name | E3: intent | F3: speech_act | G3: text_raw | H3: text_spoken | I3: language_mix | J3: norm_features | K3: lexicon_variant | L3: speaker_region | M3: speaker_state | N3: factors_covered | O3: so_am_tiet | P3: do_dai | Q3: est_duration_s | R3: notes
A4: CS01-M1-001 | B4: M1 | C4: CS01 | D4: =IFERROR(INDEX(Case_study!$B$4:$B$15,MATCH(C4,Case_study!$A$4:$A$15,0)),"") -> Dẫn đường | E4: dẫn đường đến địa chỉ | F4: Lệnh | G4: Dẫn đường đến số 15 ngõ 28 Chùa Bộc. | H4: Dẫn đường đến số mười lăm ngõ hai mươi tám Chùa Bộc. | I4: Việt | J4: số; địa chỉ; tên riêng/địa danh | K4: Bắc | L4: Bắc | M4: Bình thường | N4: E03; E04; S51; S54 | O4: =LEN(TRIM(H4))-LEN(SUBSTITUTE(TRIM(H4)," ",""))+1 -> 12 | P4: =IF(O4<=3,"Rất ngắn (≤3)",IF(O4<=8,"Ngắn (4–8)","Thường (>8)")) -> Thường (>8) | Q4: =ROUND(O4/Tong_quan!$B$40,1) -> 2.7 | R4: Cần người bản ngữ vùng đó duyệt.
A5: CS01-M1-002 | B5: M1 | C5: CS01 | D5: =IFERROR(INDEX(Case_study!$B$4:$B$15,MATCH(C5,Case_study!$A$4:$A$15,0)),"") -> Dẫn đường | E5: dẫn đường đến địa chỉ | F5: Lệnh | G5: Dẫn đường tới hẻm 28 đường Nguyễn Văn Cừ. | H5: Dẫn đường tới hẻm hai mươi tám đường Nguyễn Văn Cừ. | I5: Việt | J5: số; địa chỉ; tên riêng/địa danh | K5: Nam | L5: Nam | M5: Bình thường | N5: E03; E04; S51; S54 | O5: =LEN(TRIM(H5))-LEN(SUBSTITUTE(TRIM(H5)," ",""))+1 -> 11 | P5: =IF(O5<=3,"Rất ngắn (≤3)",IF(O5<=8,"Ngắn (4–8)","Thường (>8)")) -> Thường (>8) | Q5: =ROUND(O5/Tong_quan!$B$40,1) -> 2.4 | R5: Cần người bản ngữ vùng đó duyệt.
A6: CS01-M1-003 | B6: M1 | C6: CS01 | D6: =IFERROR(INDEX(Case_study!$B$4:$B$15,MATCH(C6,Case_study!$A$4:$A$15,0)),"") -> Dẫn đường | E6: hỏi còn bao xa | F6: Câu hỏi | G6: Còn bao xa nữa thì đến nơi? | H6: Còn bao xa nữa thì đến nơi? | I6: Việt | K6: Chuẩn chung | L6: Bất kỳ (xoay vòng) | M6: Bình thường | N6: E08; S33 | O6: =LEN(TRIM(H6))-LEN(SUBSTITUTE(TRIM(H6)," ",""))+1 -> 7 | P6: =IF(O6<=3,"Rất ngắn (≤3)",IF(O6<=8,"Ngắn (4–8)","Thường (>8)")) -> Ngắn (4–8) | Q6: =ROUND(O6/Tong_quan!$B$40,1) -> 1.6
A7: CS01-M1-004 | B7: M1 | C7: CS01 | D7: =IFERROR(INDEX(Case_study!$B$4:$B$15,MATCH(C7,Case_study!$A$4:$A$15,0)),"") -> Dẫn đường | E7: báo rẽ ở ngã tư | F7: Câu hỏi | G7: Quẹo trái ở ngã tư tới đúng không? | H7: Quẹo trái ở ngã tư tới đúng không? | I7: Việt | K7: Nam | L7: Nam | M7: Bình thường | N7: S51; S33 | O7: =LEN(TRIM(H7))-LEN(SUBSTITUTE(TRIM(H7)," ",""))+1 -> 8 | P7: =IF(O7<=3,"Rất ngắn (≤3)",IF(O7<=8,"Ngắn (4–8)","Thường (>8)")) -> Ngắn (4–8) | Q7: =ROUND(O7/Tong_quan!$B$40,1) -> 1.8 | R7: Cần người bản ngữ vùng đó duyệt.
A8: CS01-M1-005 | B8: M1 | C8: CS01 | D8: =IFERROR(INDEX(Case_study!$B$4:$B$15,MATCH(C8,Case_study!$A$4:$A$15,0)),"") -> Dẫn đường | E8: tìm đường tránh tắc | F8: Lệnh | G8: Tìm đường khác tránh kẹt xe. | H8: Tìm đường khác tránh kẹt xe. | I8: Việt | K8: Nam | L8: Nam | M8: Bình thường | N8: S51 | O8: =LEN(TRIM(H8))-LEN(SUBSTITUTE(TRIM(H8)," ",""))+1 -> 6 | P8: =IF(O8<=3,"Rất ngắn (≤3)",IF(O8<=8,"Ngắn (4–8)","Thường (>8)")) -> Ngắn (4–8) | Q8: =ROUND(O8/Tong_quan!$B$40,1) -> 1.3 | R8: Cần người bản ngữ vùng đó duyệt.
A9: CS01-M1-006 | B9: M1 | C9: CS01 | D9: =IFERROR(INDEX(Case_study!$B$4:$B$15,MATCH(C9,Case_study!$A$4:$A$15,0)),"") -> Dẫn đường | E9: tìm đường tránh tắc | F9: Lệnh | G9: Tìm đường khác tránh tắc đường. | H9: Tìm đường khác tránh tắc đường. | I9: Việt | K9: Bắc | L9: Bắc | M9: Bình thường | N9: S51 | O9: =LEN(TRIM(H9))-LEN(SUBSTITUTE(TRIM(H9)," ",""))+1 -> 6 | P9: =IF(O9<=3,"Rất ngắn (≤3)",IF(O9<=8,"Ngắn (4–8)","Thường (>8)")) -> Ngắn (4–8) | Q9: =ROUND(O9/Tong_quan!$B$40,1) -> 1.3 | R9: Cần người bản ngữ vùng đó duyệt.
A10: CS01-M1-007 | B10: M1 | C10: CS01 | D10: =IFERROR(INDEX(Case_study!$B$4:$B$15,MATCH(C10,Case_study!$A$4:$A$15,0)),"") -> Dẫn đường | E10: hỏi giờ đến | F10: Câu hỏi | G10: Đến Huế mất bao lâu? | H10: Đến Huế mất bao lâu? | I10: Việt | J10: tên riêng/địa danh | K10: Chuẩn chung | L10: Trung | M10: Bình thường | N10: E04; E08 | O10: =LEN(TRIM(H10))-LEN(SUBSTITUTE(TRIM(H10)," ",""))+1 -> 5 | P10: =IF(O10<=3,"Rất ngắn (≤3)",IF(O10<=8,"Ngắn (4–8)","Thường (>8)")) -> Ngắn (4–8) | Q10: =ROUND(O10/Tong_quan!$B$40,1) -> 1.1 | R10: Giọng Trung nói tên địa danh Trung; từ vựng chuẩn chung.
A11: CS01-M1-008 | B11: M1 | C11: CS01 | D11: =IFERROR(INDEX(Case_study!$B$4:$B$15,MATCH(C11,Case_study!$A$4:$A$15,0)),"") -> Dẫn đường | E11: hủy dẫn đường | F11: Lệnh | G11: Hủy dẫn đường. | H11: Hủy dẫn đường. | I11: Việt | K11: Chuẩn chung | L11: Bất kỳ (xoay vòng) | M11: Bình thường | N11: E08 | O11: =LEN(TRIM(H11))-LEN(SUBSTITUTE(TRIM(H11)," ",""))+1 -> 3 | P11: =IF(O11<=3,"Rất ngắn (≤3)",IF(O11<=8,"Ngắn (4–8)","Thường (>8)")) -> Rất ngắn (≤3) | Q11: =ROUND(O11/Tong_quan!$B$40,1) -> 0.7
A12: CS02-M1-001 | B12: M1 | C12: CS02 | D12: =IFERROR(INDEX(Case_study!$B$4:$B$15,MATCH(C12,Case_study!$A$4:$A$15,0)),"") -> Cảnh báo an toàn (ADAS) | E12: tắt cảnh báo | F12: Lệnh | G12: Tắt cảnh báo lệch làn. | H12: Tắt cảnh báo lệch làn. | I12: Việt | K12: Chuẩn chung | L12: Bất kỳ (xoay vòng) | M12: Bình thường | N12: E08 | O12: =LEN(TRIM(H12))-LEN(SUBSTITUTE(TRIM(H12)," ",""))+1 -> 5 | P12: =IF(O12<=3,"Rất ngắn (≤3)",IF(O12<=8,"Ngắn (4–8)","Thường (>8)")) -> Ngắn (4–8) | Q12: =ROUND(O12/Tong_quan!$B$40,1) -> 1.1
A13: CS02-M1-002 | B13: M1 | C13: CS02 | D13: =IFERROR(INDEX(Case_study!$B$4:$B$15,MATCH(C13,Case_study!$A$4:$A$15,0)),"") -> Cảnh báo an toàn (ADAS) | E13: nói tôi ổn khi bị nhắc mệt | F13: Câu cụt | G13: Tôi tỉnh rồi, không cần nhắc nữa. | H13: Tôi tỉnh rồi, không cần nhắc nữa. | I13: Việt | K13: Chuẩn chung | L13: Bất kỳ (xoay vòng) | M13: Mệt mỏi | N13: S22; S23; D03 | O13: =LEN(TRIM(H13))-LEN(SUBSTITUTE(TRIM(H13)," ",""))+1 -> 7 | P13: =IF(O13<=3,"Rất ngắn (≤3)",IF(O13<=8,"Ngắn (4–8)","Thường (>8)")) -> Ngắn (4–8) | Q13: =ROUND(O13/Tong_quan!$B$40,1) -> 1.6 | R13: Giọng mệt khó sinh; xem yếu tố S22.
